Workbook

Sheet Quiet Scout Analysemodel
A1: QUIET SCOUT v0.1 — Website Analysemodel
A2: BASIS | D2: OUDE INTERNETSTRUCTUREN (score 1–5) | N2: MENTALE BELASTING (score 1–5) | R2: BESLISSINGSZWAARTE (score 1–5) | W2: QUIET WEB POTENTIE (score 1–5) | AA2: QUIET SCORE | AB2: FOUT-CONSEQUENTIE
A3: Website | B3: Categorie | C3: URL | D3: Filter-overload | E3: Vergelijk-stress | F3: Formulier-denken | G3: Verborgen logica | H3: Eindeloos scrollen | I3: Paginering-probleem | J3: Keuze-stress | K3: Systeem-denken | L3: Gebruiker doet het werk | M3: Begrips- drempel | N3: Cognitieve druk | O3: Onzekerheid | P3: Hoeveelheid keuzes | Q3: Hoeveelheid interpretatie | R3: Angst voor fouten | S3: Financiële impact | T3: Juridische impact | U3: Kwetsbaar- heid user | V3: Afhankelijk- heid systeem | W3: Intentie vervangt filters | X3: AI reduceert keuzes | Y3: AI begeleidt gebruiker | Z3: Systeem kan rustiger | AA3: Quiet Score | AB3: Wat gebeurt er als de gebruiker het fout begrijpt? | AC3: Observatie 1 — oud patroon | AD3: Observatie 2 — mentale last | AE3: Observatie 3 — AI kans | AF3: Observatie 4 — rustpotentie | AG3: Positieve elementen | AH3: Doelgroep | AI3: Traffic inschatting | AJ3: Businessmodel | AK3: Concurrenten | AL3: Prioriteit voor Quiet Web | AM3: Datum analyse
A4: funda.nl | B4: Vastgoed | C4: https://funda.nl | D4: 5 | E4: 3 | F4: 4 | G4: 3 | H4: 2 | I4: 4 | J4: 4 | K4: 5 | L4: 5 | N4: 4 | O4: 3 | P4: 5 | Q4: 4 | R4: 3 | S4: 4 | T4: 2 | U4: 2 | V4: 3 | W4: 5 | X4: 4 | Y4: 5 | Z4: 4 | AA4: =ROUND(AVERAGE(D4:M4)*0.25+AVERAGE(N4:Q4)*0.2+AVERAGE(R4:V4)*0.3+AVERAGE(W4:Z4)*0.25,1) -> 3.7 | AB4: Bod uitgebracht op basis van verkeerd begrepen energielabel of VvE-kosten. Contractueel bindend. | AC4: 23+ filteropties; gebruiker sorteert 800+ resultaten zelf | AD4: Onzekerheid over 'woonhuis' vs 'eengezinswoning' — systeemtermen, geen gebruikerstermen | AE4: Intentie 'rustig huis nabij school' kan alle filters vervangen | AF4: Begeleide zoekflow op basis van situatie vervangt filterlade | AG4: Grote fotoseries, kaartweergave, buurtinfo | AH4: Huizenkopers 25–55 | AI4: Zeer hoog (837M p/j) | AJ4: Lead gen via makelaars | AK4: Pararius, Husl, Walter Living | AL4: Zeer hoog | AM4: 2025-05-18
A5: pararius.nl | B5: Vastgoed | C5: https://pararius.nl | D5: 3 | E5: 2 | F5: 3 | G5: 4 | H5: 3 | I5: 3 | J5: 3 | K5: 3 | L5: 4 | N5: 3 | O5: 4 | P5: 3 | Q5: 3 | R5: 3 | S5: 3 | T5: 2 | U5: 3 | V5: 3 | W5: 4 | X5: 3 | Y5: 4 | Z5: 4 | AA5: =ROUND(AVERAGE(D5:M5)*0.25+AVERAGE(N5:Q5)*0.2+AVERAGE(R5:V5)*0.3+AVERAGE(W5:Z5)*0.25,1) -> 3.2 | AB5: Huurcontract getekend bij verhuurder die listing al verwijderd had. Geen verhaal via platform. | AC5: Gebruiker doorgestuurd naar makelaarsite: twee systemen leren | AD5: Verborgen logica: verouderde listings blijven staan na verhuur | AE5: Situatiecheck 'expat, 6 maanden, huisdier' → direct gefilterd aanbod | AF5: Één flow van zoeken tot contactmoment, geen redirect naar externe sites | AG5: Alerts werken goed, breed aanbod | AH5: Huurders incl. expats | AI5: Hoog | AJ5: Commissie makelaars | AK5: Huurwoningen.nl, Funda huur | AL5: Midden | AM5: 2025-05-18
A6: independer.nl | B6: Vergelijker | C6: https://independer.nl | D6: 4 | E6: 5 | F6: 5 | G6: 3 | H6: 1 | I6: 2 | J6: 5 | K6: 4 | L6: 5 | N6: 4 | O6: 5 | P6: 5 | Q6: 5 | R6: 4 | S6: 4 | T6: 3 | U6: 3 | V6: 3 | W6: 5 | X6: 5 | Y6: 5 | Z6: 5 | AA6: =ROUND(AVERAGE(D6:M6)*0.25+AVERAGE(N6:Q6)*0.2+AVERAGE(R6:V6)*0.3+AVERAGE(W6:Z6)*0.25,1) -> 4.2 | AB6: Verkeerd eigen risico gekozen = honderden euro's onverwachte kosten bij eerste zorggebruik. | AC6: Gebruiker moet verzekeringssystematiek begrijpen vóór eerste keuze | AD6: 30+ opties zonder context wie wat nodig heeft; eigen risico veronderstelt marktkennis | AE6: Situatiebeschrijving (chronisch ziek, fysiotherapeut) → directe aanbeveling | AF6: Van vergelijkingstabel naar persoonlijk keuzegids | AG6: Breed aanbod, sluitingsdatum automatisch | AH6: Consumenten alle leeftijden | AI6: Zeer hoog | AJ6: Commissie per afsluiting | AK6: Pricewise, Zorgwijzer, Consumentenbond | AL6: Zeer hoog | AM6: 2025-05-18
A7: gaslicht.com | B7: Energie | C7: https://gaslicht.com | D7: 3 | E7: 4 | F7: 5 | G7: 4 | H7: 1 | I7: 1 | J7: 4 | K7: 5 | L7: 5 | N7: 5 | O7: 5 | P7: 4 | Q7: 5 | R7: 3 | S7: 3 | T7: 1 | U7: 2 | V7: 2 | W7: 5 | X7: 5 | Y7: 4 | Z7: 5 | AA7: =ROUND(AVERAGE(D7:M7)*0.25+AVERAGE(N7:Q7)*0.2+AVERAGE(R7:V7)*0.3+AVERAGE(W7:Z7)*0.25,1) -> 3.7 | AB7: Variabel contract gekozen bij verkeerd marktmoment = energierekening verdubbeld. | AC7: Invoer vereist kWh/m³ — getallen die gebruiker niet kent | AD7: Vast vs variabel: marktkennis vereist voor verantwoorde keuze | AE7: Woningtype + personen + postcode → direct beste deal zonder energiekennis | AF7: Van tariefstabel naar situatieadvies in één stap | AG7: Actuele tarieven, iDIN-koppeling verbruik | AH7: Huishoudens 25–65 | AI7: Hoog | AJ7: Commissie energieleverancier | AK7: Pricewise, Energievergelijk | AL7: Hoog | AM7: 2025-05-18
A8: pricewise.nl | B8: Vergelijker | C8: https://pricewise.nl | D8: 4 | E8: 4 | F8: 4 | G8: 3 | H8: 1 | I8: 2 | J8: 5 | K8: 4 | L8: 5 | N8: 4 | O8: 4 | P8: 5 | Q8: 4 | R8: 3 | S8: 3 | T8: 2 | U8: 2 | V8: 2 | W8: 5 | X8: 4 | Y8: 5 | Z8: 4 | AA8: =ROUND(AVERAGE(D8:M8)*0.25+AVERAGE(N8:Q8)*0.2+AVERAGE(R8:V8)*0.3+AVERAGE(W8:Z8)*0.25,1) -> 3.6 | AB8: Overstap te snel gedaan zonder opzegtermijn = dubbele abonnementskosten. | AC8: 23 categorieën te vergelijken — breedte creëert oriëntatieparalyse | AD8: Gebruiker weet niet bij welke categorie te beginnen; energie, zorg, telecom tegelijk | AE8: Profiel 'huishouden, budget, prioriteiten' → gesorteerde actielijst | AF8: Gelaagd: eerst meest urgente besparing, dan rest | AG8: Exclusieve kortingen, breed aanbod | AH8: Breed publiek, kostenbewust | AI8: Hoog | AJ8: Commissie per afsluiting | AK8: Independer, Gaslicht, Consumentenbond | AL8: Hoog | AM8: 2025-05-18
A9: zorgwijzer.nl | B9: Zorg | C9: https://zorgwijzer.nl | D9: 3 | E9: 5 | F9: 4 | G9: 4 | H9: 1 | I9: 2 | J9: 5 | K9: 5 | L9: 5 | N9: 5 | O9: 5 | P9: 5 | Q9: 5 | R9: 4 | S9: 4 | T9: 2 | U9: 3 | V9: 4 | W9: 5 | X9: 5 | Y9: 5 | Z9: 5 | AA9: =ROUND(AVERAGE(D9:M9)*0.25+AVERAGE(N9:Q9)*0.2+AVERAGE(R9:V9)*0.3+AVERAGE(W9:Z9)*0.25,1) -> 4.2 | AB9: Verkeerde polis = fysiotherapeut of specialist niet vergoed. Pas ontdekt bij eerste declaratie na 1 januari. | AC9: Naturapolis vs combinatiepolis: juridisch verschil, niet begrijpelijk voor leek | AD9: Keuzemoment december: tijdsdruk + maximale onzekerheid gecombineerd | AE9: Situatieprofiel (chronisch, gezond, gezin) → top-3 direct, zonder polis-jargon | AF9: Geen tabel maar gesprek: 'wat gebruik je het meest?' | AG9: Zorgexperts bereikbaar, automatisch opzeggen | AH9: Zorgverzekerden NL, jaarlijks beslissmoment | AI9: Zeer hoog (dec/jan) | AJ9: Commissie verzekeraar | AK9: Independer, Consumentenbond, Poliswijzer | AL9: Zeer hoog | AM9: 2025-05-18
A10: nationalevacaturebank.nl | B10: Werk | C10: https://nationalevacaturebank.nl | D10: 3 | E10: 2 | F10: 4 | G10: 3 | H10: 3 | I10: 4 | J10: 4 | K10: 4 | L10: 5 | N10: 4 | O10: 4 | P10: 4 | Q10: 5 | R10: 3 | S10: 3 | T10: 2 | U10: 4 | V10: 2 | W10: 5 | X10: 4 | Y10: 5 | Z10: 4 | AA10: =ROUND(AVERAGE(D10:M10)*0.25+AVERAGE(N10:Q10)*0.2+AVERAGE(R10:V10)*0.3+AVERAGE(W10:Z10)*0.25,1) -> 3.7 | AB10: Sollicitatie ingediend op functie die al ingevuld was. Verwachtingen gewekt die niet kloppen. | AC10: Vraagt functietitel terwijl gebruiker juist die zoekt | AD10: Sectorkeuze sluit niet aan op hoe werkzoekenden denken | AE10: Ambities + waarden + werkomgeving → passende vacatures zonder functietitel | AF10: Begeleide oriëntatie vervangt zoekbalk | AG10: Breed nationaal aanbod | AH10: Werkzoekenden alle niveaus | AI10: Hoog | AJ10: Advertenties/werving | AK10: Indeed, LinkedIn, Werk.nl | AL10: Hoog | AM10: 2025-05-18
A11: indeed.nl | B11: Werk | C11: https://indeed.nl | D11: 3 | E11: 2 | F11: 3 | G11: 3 | H11: 4 | I11: 3 | J11: 3 | K11: 3 | L11: 4 | N11: 3 | O11: 3 | P11: 4 | Q11: 3 | R11: 2 | S11: 3 | T11: 2 | U11: 3 | V11: 2 | W11: 4 | X11: 4 | Y11: 4 | Z11: 3 | AA11: =ROUND(AVERAGE(D11:M11)*0.25+AVERAGE(N11:Q11)*0.2+AVERAGE(R11:V11)*0.3+AVERAGE(W11:Z11)*0.25,1) -> 3.1 | AB11: CV-data gedeeld met derde partijen. Lage directe consequentie. | AC11: Eindeloos scrollen door gesponsorde + organische vacatures door elkaar | AD11: Zelfde vacature van 5 uitzendbureaus: gebruiker telt dubbel | AE11: Intentie + werkprofiel → relevantiescore per vacature | AF11: Gesponsord scheiden van organisch; dubbelingen clusteren | AG11: Groot bereik, snelle sollicitatie, bedrijfsreviews | AH11: Breed, actieve werkzoekenden | AI11: Zeer hoog | AJ11: CPC advertenties | AK11: LinkedIn, Nationalevacaturebank | AL11: Midden | AM11: 2025-05-18
A12: werkzoeken.nl | B12: Werk | C12: https://werkzoeken.nl | D12: 3 | E12: 1 | F12: 3 | G12: 2 | H12: 3 | I12: 3 | J12: 3 | K12: 3 | L12: 4 | N12: 2 | O12: 3 | P12: 3 | Q12: 3 | R12: 2 | S12: 2 | T12: 1 | U12: 3 | V12: 2 | W12: 3 | X12: 3 | Y12: 3 | Z12: 3 | AA12: =ROUND(AVERAGE(D12:M12)*0.25+AVERAGE(N12:Q12)*0.2+AVERAGE(R12:V12)*0.3+AVERAGE(W12:Z12)*0.25,1) -> 2.6 | AB12: Geen sollicitatieplicht — vrijblijvend. Lage consequentie. | AC12: Standaard vacaturebank-layout: zoekterm + regio, geen verdere begeleiding | AD12: Beperkte filteropties; gebruiker zoekt op trefwoord zonder context | AE12: Werkprofiel → aanbod zonder zoekterm | AF12: Persoonlijke matching op basis van profiel | AG12: Overzichtelijk, snel laden | AH12: MBO/HBO werkzoekenden | AI12: Midden | AJ12: Advertenties | AK12: Indeed, Nationalevacaturebank | AL12: Laag | AM12: 2025-05-18
A13: belastingdienst.nl | B13: Overheid | C13: https://belastingdienst.nl | D13: 2 | E13: 1 | F13: 5 | G13: 5 | H13: 1 | I13: 1 | J13: 4 | K13: 5 | L13: 5 | N13: 5 | O13: 5 | P13: 3 | Q13: 5 | R13: 4 | S13: 5 | T13: 4 | U13: 3 | V13: 5 | W13: 4 | X13: 3 | Y13: 5 | Z13: 4 | AA13: =ROUND(AVERAGE(D13:M13)*0.25+AVERAGE(N13:Q13)*0.2+AVERAGE(R13:V13)*0.3+AVERAGE(W13:Z13)*0.25,1) -> 4 | AB13: Fout in aangifte leidt tot naheffing + rente. Bezwaar kost tijd en energie. Systeem is niet vergevingsgezind. | AC13: Navigatie in ambtelijke categorieën: gebruiker zoekt taak, site biedt thema's | AD13: DigiD-drempel + browser-eisen + formulierlogica = driedubbele barrière | AE13: Taakgebaseerde ingang: 'ik wil aangifte doen' zonder voorkennis | AF13: Prefill op basis van bekende gegevens; burger hoeft minder in te voeren | AG13: Aangifte-app relatief eenvoudig; belastingtelefoon | AH13: Alle belastingplichtige Nederlanders | AI13: Zeer hoog | AJ13: Overheid | AK13: Geen directe concurrent | AL13: Hoog (hoge AI-potentie) | AM13: 2025-05-18
A14: duo.nl | B14: Overheid | C14: https://duo.nl | D14: 2 | E14: 1 | F14: 5 | G14: 5 | H14: 1 | I14: 1 | J14: 3 | K14: 5 | L14: 5 | N14: 4 | O14: 4 | P14: 3 | Q14: 5 | R14: 3 | S14: 4 | T14: 3 | U14: 3 | V14: 5 | W14: 4 | X14: 3 | Y14: 5 | Z14: 4 | AA14: =ROUND(AVERAGE(D14:M14)*0.25+AVERAGE(N14:Q14)*0.2+AVERAGE(R14:V14)*0.3+AVERAGE(W14:Z14)*0.25,1) -> 3.7 | AB14: OV-kaart te laat stopgezet = maanden onterecht gebruik, terugvordering. | AC14: Studenten zoeken 'lening aanvragen'; DUO biedt categoriestructuur van uitvoeringsorganisatie | AD14: Begrippen als 'prestatiebeurs', 'basisbeurs' zijn intern jargon, niet de taal van de student | AE14: Levenssituatie student → automatisch correct leenscenario zonder jargon | AF14: Gepersonaliseerd dashboard: wat moet ik doen, wanneer, hoeveel | AG14: Formulieren online afhandelbaar, berichten via MijnDUO | AH14: Studenten, ex-studenten, instellingen | AI14: Hoog | AJ14: Overheid | AK14: Geen directe concurrent | AL14: Hoog | AM14: 2025-05-18
A15: uwv.nl | B15: Overheid | C15: https://uwv.nl | D15: 2 | E15: 1 | F15: 5 | G15: 5 | H15: 1 | I15: 1 | J15: 3 | K15: 5 | L15: 5 | N15: 5 | O15: 5 | P15: 3 | Q15: 5 | R15: 5 | S15: 5 | T15: 4 | U15: 5 | V15: 5 | W15: 4 | X15: 3 | Y15: 5 | Z15: 5 | AA15: =ROUND(AVERAGE(D15:M15)*0.25+AVERAGE(N15:Q15)*0.2+AVERAGE(R15:V15)*0.3+AVERAGE(W15:Z15)*0.25,1) -> 4.2 | AB15: Verkeerde regeling kiezen = geen uitkering of te lage uitkering. Bezwaarprocedure vergt maanden. Kwetsbare gebruiker draagt de fout. | AC15: Gebruiker in kwetsbare situatie moet eerst uitvinden welke regeling voor hem geldt | AD15: WW, WIA, Wajong, WAO — afkortingen onbegrijpelijk voor iemand die net werkloos is | AE15: Situatie ('ik ben ontslagen, 3 jaar gewerkt') → direct juiste aanvraagflow | AF15: Aanvraag automatisch gevuld op basis van arbeidsdossier | AG15: Mijn UWV werkt redelijk, brief-notificaties aanwezig | AH15: Werklozen, arbeidsongeschikten | AI15: Hoog | AJ15: Overheid | AK15: Geen directe concurrent | AL15: Zeer hoog (kwetsbare doelgroep) | AM15: 2025-05-18
... A43: 9292.nl | B43: OV/Reizen | C43: https://9292.nl | D43: 2 | E43: 1 | F43: 2 | G43: 3 | H43: 1 | I43: 1 | J43: 2 | K43: 3 | L43: 3 | N43: 2 | O43: 2 | P43: 2 | Q43: 3 | R43: 1 | S43: 2 | T43: 1 | U43: 1 | V43: 3 | W43: 3 | X43: 3 | Y43: 3 | Z43: 3 | AA43: =ROUND(AVERAGE(D43:M43)*0.25+AVERAGE(N43:Q43)*0.2+AVERAGE(R43:V43)*0.3+AVERAGE(W43:Z43)*0.25,1) -> 2.2 | AB43: Verkeerde trein nemen — herstelbaar. Lage consequentie. | AC43: Reisplanner goed maar: geen context waarom alternatieve route beter kan zijn | AD43: OV-chipkaart saldo niet zichtbaar in planningsflow — losgekoppeld systeem | AE43: Vertrekintentie + OV-kaart status → complete reisadvies incl. saldowaarschuwing | AF43: Proactieve melding: 'uw gebruikelijke trein heeft 12 minuten vertraging' | AG43: Eenvoudige interface, betrouwbare data, goede app — tweede controlepunt | AH43: OV-reizigers NL | AI43: Hoog | AJ43: Overheid/NS/vervoerders | AK43: NS, Google Maps | AL43: Laag (al redelijk goed) | AM43: 2025-05-18
A44: toeslagen.nl | B44: Overheid | C44: https://toeslagen.nl | D44: 1 | E44: 1 | F44: 5 | G44: 5 | H44: 1 | I44: 1 | J44: 4 | K44: 5 | L44: 5 | M44: 5 | N44: 5 | O44: 5 | P44: 3 | Q44: 5 | R44: 5 | S44: 5 | T44: 4 | U44: 5 | V44: 5 | W44: 4 | X44: 3 | Y44: 5 | Z44: 5 | AA44: =ROUND(AVERAGE(D44:M44)*0.25+AVERAGE(N44:Q44)*0.2+AVERAGE(R44:V44)*0.3+AVERAGE(W44:Z44)*0.25,1) -> 4.2 | AB44: Terugvordering van soms duizenden euro's, soms jaren later. Toeslagenaffaire toont aan: systeemfouten worden op de gebruiker verhaald. | AC44: Toeslagpartner, toetsingsinkomen, terugvorderingen — elk begrip is een barrière | AD44: Burger weet niet of hij recht heeft tot hij alles ingevuld heeft — pas dan volgt antwoord | AE44: Situatieprofiel (huur, inkomen, gezin) → direct overzicht recht + bedrag | AF44: Proactief: 'u heeft mogelijk recht op huurtoeslag, wilt u dat checken?' | AG44: Proefberekening aanwezig | AH44: Huurders, laag inkomen NL | AI44: Zeer hoog | AJ44: Overheid | AK44: Geen directe concurrent | AL44: Zeer hoog | AM44: 2025-05-18
A45: mijnpensioenoverzicht.nl | B45: Financieel/Overheid | C45: https://mijnpensioenoverzicht.nl | D45: 1 | E45: 1 | F45: 4 | G45: 5 | H45: 1 | I45: 1 | J45: 3 | K45: 5 | L45: 4 | M45: 5 | N45: 4 | O45: 5 | P45: 2 | Q45: 5 | R45: 4 | S45: 5 | T45: 3 | U45: 4 | V45: 4 | W45: 4 | X45: 4 | Y45: 5 | Z45: 5 | AA45: =ROUND(AVERAGE(D45:M45)*0.25+AVERAGE(N45:Q45)*0.2+AVERAGE(R45:V45)*0.3+AVERAGE(W45:Z45)*0.25,1) -> 3.9 | AB45: Niet begrijpen = niets doen. Pensioengat ontstaat ongemerkt. Consequentie pas zichtbaar over tientallen jaren. | AC45: UPO, AOW-gat, slapersrechten, dekkingsgraad — pensioenlandschap is jargon-jungle | AD45: Gebruiker ziet getal maar begrijpt niet of het genoeg is, te weinig, of wat te doen | AE45: Situatie-scanner: 'bent u op schema?' met concrete aanbeveling | AF45: Handelingsperspectief: 'op basis van uw situatie raden we X aan' | AG45: Totaaloverzicht alle pensioenen op één plek, DigiD-login | AH45: Werkenden + gepensioneerden NL | AI45: Hoog | AJ45: Overheid/Pensioenfederatie | AK45: Geen directe concurrent | AL45: Hoog | AM45: 2025-05-18
A46: svb.nl | B46: Overheid | C46: https://svb.nl | D46: 1 | E46: 1 | F46: 5 | G46: 5 | H46: 1 | I46: 1 | J46: 3 | K46: 5 | L46: 5 | M46: 5 | N46: 4 | O46: 5 | P46: 3 | Q46: 5 | R46: 4 | S46: 5 | T46: 4 | U46: 4 | V46: 5 | W46: 3 | X46: 3 | Y46: 5 | Z46: 4 | AA46: =ROUND(AVERAGE(D46:M46)*0.25+AVERAGE(N46:Q46)*0.2+AVERAGE(R46:V46)*0.3+AVERAGE(W46:Z46)*0.25,1) -> 3.9 | AB46: AOW te laat aangevraagd = uitkering start later. Niet met terugwerkende kracht. | AC46: AOW, ANW, AKW, PGB-trekkingsrecht — SVB beheert meerdere regelingen met elk eigen jargon | AD46: Burger weet niet welke SVB-dienst voor hem relevant is tot hij de hele site doorgespit heeft | AE46: Levenssituatie-ingang: 'ik word 67' of 'mijn partner is overleden' → direct relevante informatie | AF46: Proactieve AOW-aanvraag: systeem weet wanneer u 67 wordt | AG46: Betrouwbaar, breed aanbod regelingen | AH46: Ouderen, nabestaanden, pgb-houders NL | AI46: Hoog | AJ46: Overheid | AK46: Geen directe concurrent | AL46: Hoog | AM46: 2025-05-18
A47: rechtsbijstandverzekering.nl | B47: Vergelijker | C47: https://rechtsbijstandverzekering.nl | D47: 3 | E47: 4 | F47: 5 | G47: 5 | H47: 1 | I47: 2 | J47: 5 | K47: 5 | L47: 5 | M47: 5 | N47: 5 | O47: 5 | P47: 4 | Q47: 5 | R47: 4 | S47: 4 | T47: 4 | U47: 3 | V47: 3 | W47: 5 | X47: 5 | Y47: 5 | Z47: 5 | AA47: =ROUND(AVERAGE(D47:M47)*0.25+AVERAGE(N47:Q47)*0.2+AVERAGE(R47:V47)*0.3+AVERAGE(W47:Z47)*0.25,1) -> 4.3 | AB47: Verkeerde module = juridisch conflict niet gedekt. Pas ontdekt als het conflict al loopt. Achteraf aanpassen niet mogelijk. | AC47: Modules (consument, wonen, werk, verkeer) veronderstellen juridisch inzicht | AD47: Gebruiker weet niet welke conflicten hij kan verwachten — kiest blind | AE47: Levenssituatie + risicogevoel → direct module-advies zonder juridisch inzicht | AF47: Van polis-opbouw naar 'dit is wat u nodig heeft' | AG47: Gespecialiseerde vergelijker, uitgebreide uitleg | AH47: Huizenbezitters, werknemers, consumenten | AI47: Hoog | AJ47: Commissie verzekeraars | AK47: Independer, Geld.nl, Pricewise | AL47: Hoog | AM47: 2025-05-18
A48: verzekering.nl | B48: Vergelijker | C48: https://verzekering.nl | D48: 4 | E48: 5 | F48: 5 | G48: 4 | H48: 1 | I48: 2 | J48: 5 | K48: 5 | L48: 5 | M48: 4 | N48: 5 | O48: 5 | P48: 5 | Q48: 5 | R48: 4 | S48: 4 | T48: 3 | U48: 2 | V48: 3 | W48: 5 | X48: 5 | Y48: 5 | Z48: 5 | AA48: =ROUND(AVERAGE(D48:M48)*0.25+AVERAGE(N48:Q48)*0.2+AVERAGE(R48:V48)*0.3+AVERAGE(W48:Z48)*0.25,1) -> 4.2 | AB48: Onderverzekerd = schade wordt niet vergoed. Oververzekerd = geld weggooien. Beide gevolgen ontdek je op het slechtste moment. | AC48: Alle verzekeringstypen op één platform — volledigheid creëert oriëntatieverlamming | AD48: Gebruiker weet niet of hij onderverzekerd of oververzekerd is — site geeft geen inzicht | AE48: Verzekeringscheck: 'wat hebt u al, wat mist u?' op basis van levenssituatie | AF48: Van losse polissen naar compleet beschermingsprofiel | AG48: Breed, compleet aanbod, direct afsluiten | AH48: Consumenten NL breed | AI48: Hoog | AJ48: Commissie verzekeraars | AK48: Independer, Geld.nl, Pricewise | AL48: Hoog | AM48: 2025-05-18
A49: regelhulp.nl | B49: Overheid/Zorg | C49: https://regelhulp.nl | D49: 1 | E49: 1 | F49: 4 | G49: 5 | H49: 1 | I49: 1 | J49: 3 | K49: 5 | L49: 5 | M49: 5 | N49: 5 | O49: 5 | P49: 3 | Q49: 5 | R49: 5 | S49: 4 | T49: 4 | U49: 5 | V49: 5 | W49: 4 | X49: 3 | Y49: 5 | Z49: 5 | AA49: =ROUND(AVERAGE(D49:M49)*0.25+AVERAGE(N49:Q49)*0.2+AVERAGE(R49:V49)*0.3+AVERAGE(W49:Z49)*0.25,1) -> 4.1 | AB49: Verkeerde zorgwet kiezen = verkeerd loket, vertraging, zorg niet vergoed. Mantelzorger draagt de gevolgen. | AC49: WMO, Jeugdwet, Zvw, Wlz — vier wetten voor zorg, elk met ander loket | AD49: Mantelzorger weet niet bij welke wet zijn situatie valt | AE49: Zorgsituatie-scan ('mijn moeder heeft dementie') → direct juist loket + stappenplan | AF49: Één ingang voor alle zorgwetten, gebaseerd op situatie niet wet | AG49: Breed informatieaanbod, neutraal overheidspunt | AH49: Mantelzorgers, zorgvragers NL | AI49: Hoog | AJ49: Overheid (VWS) | AK49: Geen directe concurrent | AL49: Zeer hoog | AM49: 2025-05-18
A50: svb.nl/pgb | B50: Overheid/Zorg | C50: https://svb.nl/pgb | D50: 1 | E50: 1 | F50: 5 | G50: 5 | H50: 1 | I50: 1 | J50: 3 | K50: 5 | L50: 5 | M50: 5 | N50: 5 | O50: 5 | P50: 3 | Q50: 5 | R50: 5 | S50: 4 | T50: 4 | U50: 5 | V50: 5 | W50: 3 | X50: 3 | Y50: 5 | Z50: 5 | AA50: =ROUND(AVERAGE(D50:M50)*0.25+AVERAGE(N50:Q50)*0.2+AVERAGE(R50:V50)*0.3+AVERAGE(W50:Z50)*0.25,1) -> 4.1 | AB50: Zorgovereenkomst fout ingevuld = SVB betaalt niet uit. Zorgverlener werkt onbetaald. Budgethouder raakt zorg kwijt. | AC50: Trekkingsrecht, zorgovereenkomst, budgethouder — PGB-systeem vereist administratieve expertise | AD50: Kwetsbare mensen (ernstig ziek of zorgend voor zieke) worden geconfronteerd met bureaucratie | AE50: PGB-begeleider: AI helpt bij complete administratie | AF50: Automatische declaraties op basis van zorgovereenkomst | AG50: Beschermt budgethouders, centrale betaling via SVB | AH50: Mensen met beperking, mantelzorgers | AI50: Hoog | AJ50: Overheid | AK50: Geen directe concurrent | AL50: Hoog | AM50: 2025-05-18
A51: rdw.nl | B51: Overheid | C51: https://rdw.nl | D51: 1 | E51: 1 | F51: 5 | G51: 5 | H51: 1 | I51: 1 | J51: 2 | K51: 5 | L51: 4 | M51: 4 | N51: 3 | O51: 3 | P51: 2 | Q51: 4 | R51: 3 | S51: 3 | T51: 3 | U51: 2 | V51: 5 | W51: 3 | X51: 3 | Y51: 4 | Z51: 3 | AA51: =ROUND(AVERAGE(D51:M51)*0.25+AVERAGE(N51:Q51)*0.2+AVERAGE(R51:V51)*0.3+AVERAGE(W51:Z51)*0.25,1) -> 3.1 | AB51: APK-plicht gemist = boete en auto van de weg. Buitenlands kenteken registratiefout = aansprakelijkheid. | AC51: Kentekencheck, APK, keuringsplichten — voertuigregistratie in overheidsstructuur | AD51: Gebruiker weet niet welke RDW-taak voor hem relevant is bij specifieke situatie | AE51: Voertuig-situatie-ingang: 'ik koop een auto' → checklist kenteken/APK/verzekering | AF51: Proactieve APK-herinnering via kenteken | AG51: Kentekencheck populair, breed aanbod | AH51: Automobilisten NL | AI51: Hoog | AJ51: Overheid | AK51: Geen directe concurrent | AL51: Midden | AM51: 2025-05-18
A52: lelylaan.nl | B52: Financieel | C52: https://leningvergelijker.nl | D52: 3 | E52: 5 | F52: 5 | G52: 4 | H52: 1 | I52: 2 | J52: 5 | K52: 5 | L52: 5 | M52: 5 | N52: 5 | O52: 5 | P52: 5 | Q52: 5 | R52: 5 | S52: 5 | T52: 4 | U52: 3 | V52: 3 | W52: 5 | X52: 5 | Y52: 5 | Z52: 5 | AA52: =ROUND(AVERAGE(D52:M52)*0.25+AVERAGE(N52:Q52)*0.2+AVERAGE(R52:V52)*0.3+AVERAGE(W52:Z52)*0.25,1) -> 4.5 | AC52: Persoonlijke lening, doorlopend krediet, roodstand — financieel jargon vereist | AD52: Gebruiker weet niet of lening verstandig is — site vergelijkt alleen prijs | AE52: Situatiebeoordeling: 'is lenen in uw situatie verstandig?' vóór vergelijken | AF52: Van prijsvergelijker naar verantwoord-lenen-gids | AG52: Breed aanbod, direct aanvragen | AH52: Consumenten leningbehoefte NL | AI52: Hoog | AJ52: Commissie kredietverstrekkers | AK52: Geld.nl, Independer, Pricewise | AL52: Hoog | AM52: 2025-05-18
A53: huurcommissie.nl | B53: Overheid/Wonen | C53: https://huurcommissie.nl | D53: 1 | E53: 1 | F53: 5 | G53: 5 | H53: 1 | I53: 1 | J53: 2 | K53: 5 | L53: 5 | M53: 5 | N53: 5 | O53: 5 | P53: 3 | Q53: 5 | R53: 4 | S53: 4 | T53: 4 | U53: 4 | V53: 5 | W53: 3 | X53: 3 | Y53: 5 | Z53: 5 | AA53: =ROUND(AVERAGE(D53:M53)*0.25+AVERAGE(N53:Q53)*0.2+AVERAGE(R53:V53)*0.3+AVERAGE(W53:Z53)*0.25,1) -> 3.9 | AB53: Fout formulier indienen = zaak niet-ontvankelijk. Huurder verliest recht op uitspraak over te hoge huur. | AC53: Huurprijscheck, servicekosten, gebreken, huurverhoging — elk traject ander formulier | AD53: Huurder in conflict kent rechten niet — site veronderstelt juridische basiskennis | AE53: Situatie-ingang: 'mijn verhuurder verhoogt de huur te veel' → direct juist formulier | AF53: Automatische huurprijscheck op basis van adres + kenmerken woning | AG53: Neutraal, gratis, wettelijke basis | AH53: Huurders in conflict NL | AI53: Midden | AJ53: Overheid | AK53: Geen directe concurrent | AL53: Hoog | AM53: 2025-05-18
A54: thuisarts.nl | B54: Zorg | C54: https://thuisarts.nl | D54: 1 | E54: 1 | F54: 3 | G54: 3 | H54: 2 | I54: 1 | J54: 3 | K54: 3 | L54: 3 | M54: 2 | N54: 3 | O54: 4 | P54: 2 | Q54: 3 | R54: 4 | S54: 3 | T54: 2 | U54: 4 | V54: 3 | W54: 4 | X54: 3 | Y54: 4 | Z54: 4 | AA54: =ROUND(AVERAGE(D54:M54)*0.25+AVERAGE(N54:Q54)*0.2+AVERAGE(R54:V54)*0.3+AVERAGE(W54:Z54)*0.25,1) -> 3 | AB54: Symptomen verkeerd ingeschaald = huisarts te laat bezocht. Medische consequentie. | AC54: Symptomenlijsten per aandoening — gebruiker moet zelf diagnose-richting kennen | AD54: Onzekerheid: 'is dit ernstig?' — site geeft informatie maar geen geruststelling | AE54: Symptoom-checker: 'wat voel ik?' → geruststellend advies + wanneer huisarts | AF54: Triage-light: AI beoordeelt urgentie | AG54: Betrouwbaar, NHG-richtlijnen, helder taalgebruik | AH54: Patiënten NL, zelfzorg | AI54: Hoog | AJ54: NHG/huisartsen | AK54: Gezondheid.be, Dokter.nl | AL54: Hoog | AM54: 2025-05-18
A55: zorgdomein.nl | B55: Zorg | C55: https://zorgdomein.nl | D55: 2 | E55: 2 | F55: 4 | G55: 5 | H55: 1 | I55: 1 | J55: 3 | K55: 5 | L55: 4 | M55: 5 | N55: 4 | O55: 5 | P55: 3 | Q55: 5 | R55: 4 | S55: 3 | T55: 3 | U55: 4 | V55: 4 | W55: 4 | X55: 4 | Y55: 5 | Z55: 5 | AA55: =ROUND(AVERAGE(D55:M55)*0.25+AVERAGE(N55:Q55)*0.2+AVERAGE(R55:V55)*0.3+AVERAGE(W55:Z55)*0.25,1) -> 3.9 | AB55: Niet-gecontracteerde specialist gekozen = zorgverzekeraar vergoedt minder of niet. | AC55: Verwijzingssysteem voor huisartsen en patiënten — patiënten navigeren in behandelaarsjargon | AD55: Wachttijden, polikliniek, eerste lijn/tweede lijn — begrippen onbekend voor patiënt | AE55: Zorgbehoefte + locatie → direct beste zorgverlener met wachttijd | AF55: Transparante wachttijden + automatische verwijzing | AG55: Efficiënt, breed zorgaanbod | AH55: Patiënten, huisartsen NL | AI55: Hoog | AJ55: Zorgverzekeraars/overheid | AK55: Zorgwijzer, Zorgkiezer | AL55: Hoog | AM55: 2025-05-18
A56: studielink.nl | B56: Onderwijs/Overheid | C56: https://studielink.nl | D56: 1 | E56: 1 | F56: 5 | G56: 5 | H56: 1 | I56: 1 | J56: 3 | K56: 5 | L56: 5 | M56: 5 | N56: 4 | O56: 5 | P56: 3 | Q56: 5 | R56: 4 | S56: 3 | T56: 3 | U56: 4 | V56: 4 | W56: 3 | X56: 3 | Y56: 5 | Z56: 4 | AA56: =ROUND(AVERAGE(D56:M56)*0.25+AVERAGE(N56:Q56)*0.2+AVERAGE(R56:V56)*0.3+AVERAGE(W56:Z56)*0.25,1) -> 3.7 | AB56: Deadline gemist = jaar uitstuderen of numerus fixus verlopen. Niet herstelbaar binnen studiejaar. | AC56: Inschrijving, aanmelding, numerus fixus, matching — studenten navigeren in hogeschooljargon | AD56: Student weet niet wat de deadline is of wat er met zijn inschrijving kan gebeuren | AE56: Geïntegreerde studiekeuze-aanmelding: 'ik ga studeren' → complete flow | AF56: Proactieve deadline-meldingen, intake-matching | AG56: Centrale aanmeldplek NL | AH56: Aankomende studenten NL | AI56: Hoog | AJ56: Overheid (DUO) | AK56: Direct universiteit/hogeschool | AL56: Hoog | AM56: 2025-05-18
A57: verbeterjehuis.nl | B57: Energie/Wonen | C57: https://verbeterjehuis.nl | D57: 2 | E57: 2 | F57: 4 | G57: 4 | H57: 1 | I57: 1 | J57: 3 | K57: 4 | L57: 4 | M57: 4 | N57: 4 | O57: 5 | P57: 3 | Q57: 4 | R57: 3 | S57: 4 | T57: 2 | U57: 2 | V57: 2 | W57: 5 | X57: 4 | Y57: 5 | Z57: 5 | AA57: =ROUND(AVERAGE(D57:M57)*0.25+AVERAGE(N57:Q57)*0.2+AVERAGE(R57:V57)*0.3+AVERAGE(W57:Z57)*0.25,1) -> 3.5 | AB57: Verkeerde maatregel gekozen = subsidie misgelopen of investering niet rendabel. | AC57: Subsidies, leningen, energielabels — verduurzaming heeft eigen begrippen per regeling | AD57: Gebruiker weet niet welke maatregel voor hem rendabel is | AE57: Woningprofiel → persoonlijk verduurzamingsplan met rendement en subsidies | AF57: Van maatregelenlijst naar geprioriteerd actieplan | AG57: ISDE-subsidie info, breed aanbod | AH57: Woningeigenaren NL | AI57: Hoog | AJ57: Overheid/subsidies | AK57: Milieu Centraal, Nuon, Energie.nl | AL57: Hoog | AM57: 2025-05-18
A58: kvk.nl | B58: Overheid/Zakelijk | C58: https://kvk.nl | D58: 1 | E58: 1 | F58: 5 | G58: 5 | H58: 1 | I58: 1 | J58: 3 | K58: 5 | L58: 5 | M58: 5 | N58: 4 | O58: 5 | P58: 3 | Q58: 5 | R58: 3 | S58: 3 | T58: 3 | U58: 3 | V58: 4 | W58: 3 | X58: 3 | Y58: 5 | Z58: 4 | AA58: =ROUND(AVERAGE(D58:M58)*0.25+AVERAGE(N58:Q58)*0.2+AVERAGE(R58:V58)*0.3+AVERAGE(W58:Z58)*0.25,1) -> 3.5 | AB58: Verkeerde rechtsvorm gekozen = andere fiscale behandeling, aansprakelijkheid of oprichtingskosten. | AC58: Inschrijven, SBI-codes, rechtsvorm — ondernemer start met onbekend administratief landschap | AD58: Startende ondernemer weet niet welke rechtsvorm of SBI-code van toepassing is | AE58: Ondernemerssituatie → direct juiste rechtsvorm + SBI-code + startchecklist | AF58: Wizard: 'start je bedrijf in 10 minuten' zonder jargon | AG58: Betrouwbaar, officieel register, breed informatieaanbod | AH58: Startende ondernemers NL | AI58: Hoog | AJ58: Overheid | AK58: Geen directe concurrent | AL58: Hoog | AM58: 2025-05-18
A59: zzp-nederland.nl | B59: Zakelijk/Vergelijker | C59: https://zzp-nederland.nl | D59: 3 | E59: 4 | F59: 4 | G59: 4 | H59: 2 | I59: 2 | J59: 4 | K59: 4 | L59: 4 | M59: 4 | N59: 4 | O59: 5 | P59: 4 | Q59: 4 | R59: 4 | S59: 4 | T59: 3 | U59: 3 | V59: 2 | W59: 5 | X59: 4 | Y59: 5 | Z59: 4 | AA59: =ROUND(AVERAGE(D59:M59)*0.25+AVERAGE(N59:Q59)*0.2+AVERAGE(R59:V59)*0.3+AVERAGE(W59:Z59)*0.25,1) -> 3.8 | AB59: Geen AOV afgesloten = bij ziekte direct zonder inkomen. Slechtste moment om te ontdekken. | AC59: AOV, pensioen, zzp-hypotheek, btw-aangifte — zzp-er heeft geen HR-afdeling | AD59: Zzp-er weet niet welke verzekeringen verplicht of verstandig zijn | AE59: Zzp-profiel → compleet beschermingspakket met prioritering | AF59: Van losse producten naar coherent zzp-beschermingsprofiel | AG59: Breed, praktisch, zzp-specifiek | AH59: Zzp-ers NL ~1.2M | AI59: Hoog | AJ59: Commissie/advertenties | AK59: Moneybird, Independer zzp, SNS | AL59: Hoog | AM59: 2025-05-18
A60: transavia.com | B60: Reizen | C60: https://transavia.com | D60: 2 | E60: 2 | F60: 3 | G60: 4 | H60: 1 | I60: 1 | J60: 3 | K60: 3 | L60: 3 | M60: 3 | N60: 3 | O60: 4 | P60: 3 | Q60: 3 | R60: 2 | S60: 3 | T60: 2 | U60: 2 | V60: 2 | W60: 3 | X60: 3 | Y60: 3 | Z60: 3 | AA60: =ROUND(AVERAGE(D60:M60)*0.25+AVERAGE(N60:Q60)*0.2+AVERAGE(R60:V60)*0.3+AVERAGE(W60:Z60)*0.25,1) -> 2.7 | AB60: Bagage-fout = extra kosten bij gate. Vervelend maar herstelbaar. | AC60: Bagagebeleid, stoelkeuze, tariefklassen — vliegmaatschappij-opties veronderstellen kennis | AD60: Totaalprijs pas na meerdere keuze-stappen zichtbaar | AE60: Reisprofiel → direct totaalprijs inclusief bagage + stoel | AF60: Eén prijs, geen verrassingen bij checkout | AG60: Duidelijker dan LCC-gemiddelde, NL-georiënteerd | AH60: Vakantiereizigers NL | AI60: Hoog | AJ60: Vluchten, services | AK60: easyJet, Ryanair, KLM | AL60: Midden | AM60: 2025-05-18
A61: thuiswinkel.org | B61: E-commerce/Keurmerk | C61: https://thuiswinkel.org | D61: 1 | E61: 1 | F61: 2 | G61: 3 | H61: 1 | I61: 1 | J61: 2 | K61: 3 | L61: 2 | M61: 2 | N61: 2 | O61: 2 | P61: 1 | Q61: 2 | R61: 1 | S61: 2 | T61: 1 | U61: 1 | V61: 1 | W61: 2 | X61: 2 | Y61: 2 | Z61: 2 | AA61: =ROUND(AVERAGE(D61:M61)*0.25+AVERAGE(N61:Q61)*0.2+AVERAGE(R61:V61)*0.3+AVERAGE(W61:Z61)*0.25,1) -> 1.7 | AB61: Keurmerk-check. Geen directe transactionele gevolgen. | AC61: Keurmerk-site — meer informatief dan transactioneel | AD61: Gebruiker snapt onderscheid Thuiswinkel Waarborg vs andere keurmerken niet altijd | AE61: Keurmerk-check bij twijfel over webshop | AF61: Minimale interventie nodig — relatief laag patroon-DNA | AG61: Vertrouwenssignaal voor consumenten | AH61: Consumenten online shoppen NL | AI61: Hoog | AJ61: Lidmaatschappen webshops | AK61: Trustpilot, Kiyoh | AL61: Laag (al relatief goed) | AM61: 2025-05-18
A62: praxis.nl | B62: E-commerce | C62: https://praxis.nl | D62: 3 | E62: 2 | F62: 2 | G62: 2 | H62: 3 | I62: 1 | J62: 3 | K62: 2 | L62: 3 | M62: 2 | N62: 2 | O62: 2 | P62: 3 | Q62: 2 | R62: 1 | S62: 2 | T62: 1 | U62: 1 | V62: 1 | W62: 3 | X62: 3 | Y62: 3 | Z62: 3 | AA62: =ROUND(AVERAGE(D62:M62)*0.25+AVERAGE(N62:Q62)*0.2+AVERAGE(R62:V62)*0.3+AVERAGE(W62:Z62)*0.25,1) -> 2.1 | AB62: Verkeerd product gekocht — retourneerbaar. Lage consequentie. | AC62: Productcategorieën op doe-het-zelf-manier — klant moet project kennen | AD62: Klant weet niet welke producten hij nodig heeft voor een klus | AE62: Klus-gebaseerde ingang: 'ik wil een muur schilderen' → complete boodschappenlijst | AF62: Project-planning met materiaallijst | AG62: Breed assortiment, winkellocaties | AH62: Doe-het-zelvers NL | AI62: Hoog | AJ62: Retail marge | AK62: Gamma, Hornbach, Bol.com | AL62: Midden | AM62: 2025-05-18
A63: consumentenbond.nl | B63: Vergelijker/Info | C63: https://consumentenbond.nl | D63: 2 | E63: 3 | F63: 3 | G63: 3 | H63: 2 | I63: 2 | J63: 3 | K63: 3 | L63: 3 | M63: 3 | N63: 3 | O63: 3 | P63: 3 | Q63: 3 | R63: 2 | S63: 3 | T63: 2 | U63: 2 | V63: 3 | W63: 4 | X63: 4 | Y63: 4 | Z63: 4 | AA63: =ROUND(AVERAGE(D63:M63)*0.25+AVERAGE(N63:Q63)*0.2+AVERAGE(R63:V63)*0.3+AVERAGE(W63:Z63)*0.25,1) -> 3 | AB63: Informatief. Fout-gebruik heeft geen directe consequenties. | AC63: Breed platform: verzekeringen, energie, elektronica — breedte zonder persoonlijke context | AD63: Gebruiker weet niet welke test of vergelijker voor zijn situatie relevant is | AE63: Situatie-ingang: 'ik overweeg te kopen/oversluiten/wisselen' → direct relevante test | AF63: Persoonlijk profiel: welke categorieën zijn voor u actueel? | AG63: Onafhankelijk, betrouwbaar, breed — sterk merk | AH63: Consumenten NL breed, leden | AI63: Hoog | AJ63: Lidmaatschappen | AK63: Independer, Geld.nl, Pricewise | AL63: Midden | AM63: 2025-05-18

Sheet Scorelegenda
A1: QUIET SCOUT v0.4 — Dimensies, Score & Belastingstypologie
A2: VIER DIMENSIES & WEGING
A3: Dimensie | B3: Weging | C3: Wat het meet
A4: Oude internetstructuren (D-M) | B4: 25% | C4: Filter-overload, formulierdenken, begripsdrempel etc.
A5: Mentale belasting (N-Q) | B5: 20% | C5: Cognitieve druk, onzekerheid, interpretatie
A6: Beslissingszwaarte (R-V) | B6: 30% | C6: Angst fouten, financieel, juridisch, kwetsbaarheid, afhankelijkheid
A7: Quiet Web potentie (W-Z) | B7: 25% | C7: Mate waarin AI rust en intentie kan brengen
A9: DRIE TYPEN COGNITIEVE BELASTING
A10: Type | B10: Kenmerk | C10: Voorbeelden
A11: Mechanische belasting | B11: Hoog oud, laag bes | C11: Filters, scrollen, paginering — irritatie maar geen angst
A12: Cognitieve belasting | B12: Hoog oud + men | C12: Vergelijken, interpreteren, systeemtaal leren
A13: Existentiële belasting | B13: Hoog bes + men | C13: Angst verkeerde keuze, kwetsbaar moment, consequenties
A15: BESLISSINGSZWAARTE — SUBFACTOREN
A16: Angst voor fouten | B16: 1-5 | C16: 1=geen gevolgen, 5=beslissing met grote persoonlijke impact
A17: Financiële impact | B17: 1-5 | C17: 1=nihil, 5=duizenden euro's of langdurig financieel gevolg
A18: Juridische impact | B18: 1-5 | C18: 1=geen, 5=langdurige juridische of administratieve consequenties
A19: Kwetsbaarheid gebruiker | B19: 1-5 | C19: 1=neutraal, 5=gebruiker in stressvolle/kwetsbare levenssituatie
A20: Afhankelijkheid systeem | B20: 1-5 | C20: 1=vrijblijvend, 5=verplicht gebruik, geen alternatief
A22: QUIET SCORE INTERPRETATIE
A23: 1.0 – 2.0 | B23: Laag | C23: Weinig oud gedrag, lage belasting, beperkte kans
A24: 2.1 – 3.0 | B24: Midden | C24: Gemiddeld: aanwezig maar niet dominant
A25: 3.1 – 4.0 | B25: Hoog | C25: Duidelijke patronen, echte kans voor Quiet Web
A26: 4.1 – 5.0 | B26: Top | C26: Prioriteit: hoge belasting én hoge AI-potentie
A28: BELASTING-TYPOLOGIE CLUSTERS (v0.4)
A29: Existentieel cluster | B29: Score 3.9-4.5 | C29: uwv, toeslagen, regelhulp, svb/pgb, hypotheker, werk.nl
A30: Cognitief cluster | B30: Score 3.8-4.5 | C30: independer, geld, zorgwijzer, autotrader, rechtsbijstand
A31: Mechanisch cluster | B31: Score 3.5-4.0 | C31: booking, gaslicht, pricewise, funda, marktplaats
A32: Modern (controlepunt) | B32: Score 2.0-2.5 | C32: coolblue, bol.com, 9292, thuiswinkel, praxis
A34: KERNZIN QUIET WEB
C35: Oude websites vragen gebruikers om zich aan te passen aan systeemstructuren.
C36: Quiet Web past systeemstructuren aan op menselijke intentie.
A38: NIEUW INZICHT v0.4
C39: Niet alle cognitieve belasting is hetzelfde. Existentiële belasting
C40: (angst + kwetsbaarheid + afhankelijkheid) is fundamenteel zwaarder
C41: dan mechanische of cognitieve belasting — en AI kan hier
C42: psychologische rust brengen, niet alleen gemak.

Sheet Cluster Analyse
A1: QUIET SCOUT — Cluster Analyse v0.2 | 40 sites
A2: Cluster | B2: Website | C2: Q-Score | D2: Oud | E2: Mentaal | F2: AI-pot | G2: Prioriteit | H2: Kernobservatie
A3: VERGELIJKINGSARCHITECTUREN
B4: independer.nl | C4: 4.5 | D4: 3.9 | E4: 4.8 | F4: 5 | G4: HOOG | H4: Gebruiker moet verzekeringssystematiek begrijpen vóór eerste keuze
B5: geld.nl | C5: 4.7 | D5: 4.1 | E5: 5 | F5: 5 | G5: HOOG | H5: Volledigste aanbod én de meeste velden — gebruiker verdrinkt
B6: zorgwijzer.nl | C6: 4.6 | D6: 3.7 | E6: 5 | F6: 5 | G6: HOOG | H6: Naturapolis vs combinatiepolis: juridisch, geen gebruikerstaal
B7: pricewise.nl | C7: 4.2 | D7: 3.9 | E7: 4.2 | F7: 4.8 | G7: HOOG | H7: 23 categorieën — breedte creëert oriëntatieparalyse
B8: autoverzekering.nl | C8: 4.3 | D8: 3.9 | E8: 4.2 | F8: 4.8 | G8: HOOG | H8: WA/allrisk-jargon veronderstelt automarktkennis
B9: gaslicht.com | C9: 4.3 | D9: 3.7 | E9: 5 | F9: 4.8 | G9: HOOG | H9: Invoer in kWh/m³ — gebruiker kent die getallen niet
B10: ↑ Gem. 6 sites | C10: 4.4 | D10: 3.9 | E10: 4.7 | F10: 4.9
A12: FINANCIEEL & LEVENSBESLUITEN
B13: hypotheker.nl | C13: 4.3 | D13: 2.9 | E13: 5 | F13: 4.8 | G13: HOOG | H13: NHG, annuïteiten, LTV begrijpen vóór eerste gesprek
B14: zorgkiezer.nl | C14: 4.2 | D14: 3.4 | E14: 4.5 | F14: 4.5 | G14: HOOG | H14: BIG-registratie, AGB-code — patiëntenjargon
B15: zilverenkruis.nl | C15: 3.9 | D15: 3 | E15: 4.5 | F15: 4.2 | G15: MIDDEN | H15: Pakketnamen zeggen niets; vergoedingentabel onbegrijpelijk
B16: ikbenviisi.nl | C16: 2.5 | D16: 1.7 | E16: 2.5 | F16: 4.2 | G16: LAAG | H16: Al relatief modern — ijkpunt voor Quiet Web
B17: ↑ Gem. 4 sites | C17: 3.7 | D17: 2.8 | E17: 4.1 | F17: 4.4
A19: VASTGOEDZOEKSTRUCTUREN
B20: funda.nl | C20: 3.9 | D20: 3.7 | E20: 3.8 | F20: 4.5 | G20: HOOG | H20: 23+ filteropties; 800+ resultaten; gebruiker doet het sorteren
B21: pararius.nl | C21: 3.4 | D21: 3 | E21: 3.5 | F21: 3.8 | G21: MIDDEN | H21: Redirect naar makelaarsite: gebruiker leert twee systemen
B22: ↑ Gem. 2 sites | C22: 3.6 | D22: 3.4 | E22: 3.6 | F22: 4.2
A24: FORMULIERBUREAUCRATIE
B25: uwv.nl | C25: 4.1 | D25: 2.7 | E25: 5 | F25: 4.5 | G25: ZEER HOOG | H25: Kwetsbare doelgroep + WW/WIA-jargon: maximale toegangsdrempel
B26: belastingdienst.nl | C26: 3.9 | D26: 2.7 | E26: 5 | F26: 4 | G26: HOOG | H26: Ambtelijke navigatie + DigiD + browsereisen = driedubbele barrière
B27: duo.nl | C27: 3.8 | D27: 2.7 | E27: 4.2 | F27: 4 | G27: HOOG | H27: Prestatiebeurs, basisbeurs — intern jargon, niet studenttaal
B28: amsterdam.nl | C28: 3.7 | D28: 2.6 | E28: 4.2 | F28: 3.8 | G28: MIDDEN | H28: Navigatie per taakveld, niet per levenssituatie burger
B29: mijnoverheid.nl | C29: 3.6 | D29: 2.4 | E29: 3.5 | F29: 3.5 | G29: MIDDEN | H29: Berichtenbox zonder context: moet ik actie nemen?
B30: rijksoverheid.nl | C30: 3.5 | D30: 2.7 | E30: 3.5 | F30: 3.5 | G30: MIDDEN | H30: Informatieportaal per ministerie, niet per levenssituatie
B31: ↑ Gem. 6 sites | C31: 3.8 | D31: 2.6 | E31: 4.2 | F31: 3.9
A33: WERK & FILTERMODELLEN
B34: werk.nl | C34: 3.9 | D34: 3.4 | E34: 5 | F34: 4 | G34: ZEER HOOG | H34: Kwetsbaar moment + sollicitatieplicht + systeemtaal
B35: nationalevacaturebank.nl | C35: 3.9 | D35: 3.6 | E35: 4.2 | F35: 4.5 | G35: HOOG | H35: Vraagt functietitel terwijl gebruiker die juist zoekt
B36: linkedin.nl | C36: 3.8 | D36: 3.2 | E36: 3.5 | F36: 4 | G36: MIDDEN | H36: Algoritmische feed; Premium vs gratis onduidelijk
B37: indeed.nl | C37: 3.4 | D37: 2.9 | E37: 3.2 | F37: 3.8 | G37: MIDDEN | H37: Zelfde vacature 5x van uitzendbureaus
B38: werkzoeken.nl | C38: 2.8 | D38: 2.7 | E38: 2.5 | F38: 3 | G38: LAAG | H38: Standaard vacaturebank; beperkte begeleiding
B39: ↑ Gem. 5 sites | C39: 3.6 | D39: 3.2 | E39: 3.7 | F39: 3.9
A41: REIZEN & BOOKING
B42: booking.com | C42: 4.6 | D42: 4.1 | E42: 5 | F42: 4.8 | G42: HOOG | H42: Urgency-manipulatie verhoogt druk bij al complexe keuze
B43: airbnb.nl | C43: 3.9 | D43: 3.4 | E43: 4.2 | F43: 4 | G43: HOOG | H43: Servicekosten pas bij checkout: prijs stijgt 20-40%
B44: trivago.nl | C44: 3.8 | D44: 3.1 | E44: 4.5 | F44: 3.8 | G44: MIDDEN | H44: Prijzen kloppen niet door verborgen kosten bij redirect
B45: skyscanner.nl | C45: 3.8 | D45: 3.1 | E45: 4.2 | F45: 3.8 | G45: MIDDEN | H45: Prijs bij klik hoger dan getoond — verborgen toeslagen
...

Sheet Dashboard
A1: QUIET SCOUT — Dashboard (40 sites)
A2: Overzicht geanalyseerde websites
A3: Website | B3: Quiet Score | C3: Oud patroon gem. | D3: Mentale last gem. | E3: AI potentie gem.
A4: =IFERROR('Quiet Scout Analysemodel'!A4,"") -> funda.nl | B4: =IFERROR('Quiet Scout Analysemodel'!U4,"") -> 2 | C4: =IFERROR(IF('Quiet Scout Analysemodel'!A4="","",ROUND(AVERAGE('Quiet Scout Analysemodel'!D4:L4),1)),"") -> 3.9 | D4: =IFERROR(IF('Quiet Scout Analysemodel'!A4="","",ROUND(AVERAGE('Quiet Scout Analysemodel'!M4:P4),1)),"") -> 4 | E4: =IFERROR(IF('Quiet Scout Analysemodel'!A4="","",ROUND(AVERAGE('Quiet Scout Analysemodel'!Q4:T4),1)),"") -> 3.3
A5: =IFERROR('Quiet Scout Analysemodel'!A5,"") -> pararius.nl | B5: =IFERROR('Quiet Scout Analysemodel'!U5,"") -> 3 | C5: =IFERROR(IF('Quiet Scout Analysemodel'!A5="","",ROUND(AVERAGE('Quiet Scout Analysemodel'!D5:L5),1)),"") -> 3.1 | D5: =IFERROR(IF('Quiet Scout Analysemodel'!A5="","",ROUND(AVERAGE('Quiet Scout Analysemodel'!M5:P5),1)),"") -> 3.3 | E5: =IFERROR(IF('Quiet Scout Analysemodel'!A5="","",ROUND(AVERAGE('Quiet Scout Analysemodel'!Q5:T5),1)),"") -> 2.8
A6: =IFERROR('Quiet Scout Analysemodel'!A6,"") -> independer.nl | B6: =IFERROR('Quiet Scout Analysemodel'!U6,"") -> 3 | C6: =IFERROR(IF('Quiet Scout Analysemodel'!A6="","",ROUND(AVERAGE('Quiet Scout Analysemodel'!D6:L6),1)),"") -> 3.8 | D6: =IFERROR(IF('Quiet Scout Analysemodel'!A6="","",ROUND(AVERAGE('Quiet Scout Analysemodel'!M6:P6),1)),"") -> 4.7 | E6: =IFERROR(IF('Quiet Scout Analysemodel'!A6="","",ROUND(AVERAGE('Quiet Scout Analysemodel'!Q6:T6),1)),"") -> 4
A7: =IFERROR('Quiet Scout Analysemodel'!A7,"") -> gaslicht.com | B7: =IFERROR('Quiet Scout Analysemodel'!U7,"") -> 2 | C7: =IFERROR(IF('Quiet Scout Analysemodel'!A7="","",ROUND(AVERAGE('Quiet Scout Analysemodel'!D7:L7),1)),"") -> 3.6 | D7: =IFERROR(IF('Quiet Scout Analysemodel'!A7="","",ROUND(AVERAGE('Quiet Scout Analysemodel'!M7:P7),1)),"") -> 4.7 | E7: =IFERROR(IF('Quiet Scout Analysemodel'!A7="","",ROUND(AVERAGE('Quiet Scout Analysemodel'!Q7:T7),1)),"") -> 3
A8: =IFERROR('Quiet Scout Analysemodel'!A8,"") -> pricewise.nl | B8: =IFERROR('Quiet Scout Analysemodel'!U8,"") -> 2 | C8: =IFERROR(IF('Quiet Scout Analysemodel'!A8="","",ROUND(AVERAGE('Quiet Scout Analysemodel'!D8:L8),1)),"") -> 3.6 | D8: =IFERROR(IF('Quiet Scout Analysemodel'!A8="","",ROUND(AVERAGE('Quiet Scout Analysemodel'!M8:P8),1)),"") -> 4.3 | E8: =IFERROR(IF('Quiet Scout Analysemodel'!A8="","",ROUND(AVERAGE('Quiet Scout Analysemodel'!Q8:T8),1)),"") -> 3
A9: =IFERROR('Quiet Scout Analysemodel'!A9,"") -> zorgwijzer.nl | B9: =IFERROR('Quiet Scout Analysemodel'!U9,"") -> 3 | C9: =IFERROR(IF('Quiet Scout Analysemodel'!A9="","",ROUND(AVERAGE('Quiet Scout Analysemodel'!D9:L9),1)),"") -> 3.8 | D9: =IFERROR(IF('Quiet Scout Analysemodel'!A9="","",ROUND(AVERAGE('Quiet Scout Analysemodel'!M9:P9),1)),"") -> 5 | E9: =IFERROR(IF('Quiet Scout Analysemodel'!A9="","",ROUND(AVERAGE('Quiet Scout Analysemodel'!Q9:T9),1)),"") -> 3.8
A10: =IFERROR('Quiet Scout Analysemodel'!A10,"") -> nationalevacaturebank.nl | B10: =IFERROR('Quiet Scout Analysemodel'!U10,"") -> 4 | C10: =IFERROR(IF('Quiet Scout Analysemodel'!A10="","",ROUND(AVERAGE('Quiet Scout Analysemodel'!D10:L10),1)),"") -> 3.6 | D10: =IFERROR(IF('Quiet Scout Analysemodel'!A10="","",ROUND(AVERAGE('Quiet Scout Analysemodel'!M10:P10),1)),"") -> 4 | E10: =IFERROR(IF('Quiet Scout Analysemodel'!A10="","",ROUND(AVERAGE('Quiet Scout Analysemodel'!Q10:T10),1)),"") -> 3.3
A11: =IFERROR('Quiet Scout Analysemodel'!A11,"") -> indeed.nl | B11: =IFERROR('Quiet Scout Analysemodel'!U11,"") -> 3 | C11: =IFERROR(IF('Quiet Scout Analysemodel'!A11="","",ROUND(AVERAGE('Quiet Scout Analysemodel'!D11:L11),1)),"") -> 3.1 | D11: =IFERROR(IF('Quiet Scout Analysemodel'!A11="","",ROUND(AVERAGE('Quiet Scout Analysemodel'!M11:P11),1)),"") -> 3.3 | E11: =IFERROR(IF('Quiet Scout Analysemodel'!A11="","",ROUND(AVERAGE('Quiet Scout Analysemodel'!Q11:T11),1)),"") -> 2.5
A12: =IFERROR('Quiet Scout Analysemodel'!A12,"") -> werkzoeken.nl | B12: =IFERROR('Quiet Scout Analysemodel'!U12,"") -> 3 | C12: =IFERROR(IF('Quiet Scout Analysemodel'!A12="","",ROUND(AVERAGE('Quiet Scout Analysemodel'!D12:L12),1)),"") -> 2.8 | D12: =IFERROR(IF('Quiet Scout Analysemodel'!A12="","",ROUND(AVERAGE('Quiet Scout Analysemodel'!M12:P12),1)),"") -> 2.7 | E12: =IFERROR(IF('Quiet Scout Analysemodel'!A12="","",ROUND(AVERAGE('Quiet Scout Analysemodel'!Q12:T12),1)),"") -> 2
A13: =IFERROR('Quiet Scout Analysemodel'!A13,"") -> belastingdienst.nl | B13: =IFERROR('Quiet Scout Analysemodel'!U13,"") -> 3 | C13: =IFERROR(IF('Quiet Scout Analysemodel'!A13="","",ROUND(AVERAGE('Quiet Scout Analysemodel'!D13:L13),1)),"") -> 3.2 | D13: =IFERROR(IF('Quiet Scout Analysemodel'!A13="","",ROUND(AVERAGE('Quiet Scout Analysemodel'!M13:P13),1)),"") -> 4.3 | E13: =IFERROR(IF('Quiet Scout Analysemodel'!A13="","",ROUND(AVERAGE('Quiet Scout Analysemodel'!Q13:T13),1)),"") -> 4.5
A14: =IFERROR('Quiet Scout Analysemodel'!A14,"") -> duo.nl | B14: =IFERROR('Quiet Scout Analysemodel'!U14,"") -> 3 | C14: =IFERROR(IF('Quiet Scout Analysemodel'!A14="","",ROUND(AVERAGE('Quiet Scout Analysemodel'!D14:L14),1)),"") -> 3.1 | D14: =IFERROR(IF('Quiet Scout Analysemodel'!A14="","",ROUND(AVERAGE('Quiet Scout Analysemodel'!M14:P14),1)),"") -> 3.7 | E14: =IFERROR(IF('Quiet Scout Analysemodel'!A14="","",ROUND(AVERAGE('Quiet Scout Analysemodel'!Q14:T14),1)),"") -> 3.8
A15: =IFERROR('Quiet Scout Analysemodel'!A15,"") -> uwv.nl | B15: =IFERROR('Quiet Scout Analysemodel'!U15,"") -> 5 | C15: =IFERROR(IF('Quiet Scout Analysemodel'!A15="","",ROUND(AVERAGE('Quiet Scout Analysemodel'!D15:L15),1)),"") -> 3.1 | D15: =IFERROR(IF('Quiet Scout Analysemodel'!A15="","",ROUND(AVERAGE('Quiet Scout Analysemodel'!M15:P15),1)),"") -> 4.3 | E15: =IFERROR(IF('Quiet Scout Analysemodel'!A15="","",ROUND(AVERAGE('Quiet Scout Analysemodel'!Q15:T15),1)),"") -> 4.8
... A53: =IFERROR('Quiet Scout Analysemodel'!A53,"") -> huurcommissie.nl | B53: =IFERROR('Quiet Scout Analysemodel'!U53,"") -> 4 | C53: =IFERROR(IF('Quiet Scout Analysemodel'!A53="","",ROUND(AVERAGE('Quiet Scout Analysemodel'!D53:L53),1)),"") -> 2.9 | D53: =IFERROR(IF('Quiet Scout Analysemodel'!A53="","",ROUND(AVERAGE('Quiet Scout Analysemodel'!M53:P53),1)),"") -> 4.5 | E53: =IFERROR(IF('Quiet Scout Analysemodel'!A53="","",ROUND(AVERAGE('Quiet Scout Analysemodel'!Q53:T53),1)),"") -> 4.3
A54: GEMIDDELD | B54: =IFERROR(ROUND(AVERAGEIF(A4:A53,"<>""",B4:B53),1),"") -> 2.7 | C54: =IFERROR(ROUND(AVERAGEIF(A4:A53,"<>""",C4:C53),1),"") -> 3.2 | D54: =IFERROR(ROUND(AVERAGEIF(A4:A53,"<>""",D4:D53),1),"") -> 3.9 | E54: =IFERROR(ROUND(AVERAGEIF(A4:A53,"<>""",E4:E53),1),"") -> 3.4
